<sdf version='1.7'>
  <world name='default'>
    <gravity>0 0 -9.8</gravity>
    <magnetic_field>6e-06 2.3e-05 -4.2e-05</magnetic_field>
    <atmosphere type='adiabatic'/>
    <physics type='ode'>
      <max_step_size>0.001</max_step_size>
      <real_time_factor>1</real_time_factor>
      <real_time_update_rate>1000</real_time_update_rate>
    </physics>
    <scene>
      <ambient>0.4 0.4 0.4 1</ambient>
      <background>0.7 0.7 0.7 1</background>
      <shadows>0</shadows>
    </scene>
    <wind/>
    <spherical_coordinates>
      <surface_model>EARTH_WGS84</surface_model>
      <latitude_deg>0</latitude_deg>
      <longitude_deg>0</longitude_deg>
      <elevation>0</elevation>
      <heading_deg>0</heading_deg>
    </spherical_coordinates>
    <include>
      <uri>model://sun</uri>
    </include>
    <model name="ttfestcar">

      <plugin name="diff_drive" filename="libgazebo_ros_diff_drive.so">
        <left_joint>left_wheel_joint</left_joint>
        <right_joint>right_wheel_joint</right_joint>
        <wheel_separation>0.182</wheel_separation>
        <wheel_diameter>0.088</wheel_diameter>
        <command_topic>cmd_vel</command_topic>
        <publish_odom>true</publish_odom>
        <publish_odom_tf>true</publish_odom_tf>
        <publish_wheel_tf>false</publish_wheel_tf>
        <odometry_topic>odom</odometry_topic>
      </plugin>
  
      <link name='chassis'>
        <pose>0 0 0.022 0 0 0</pose>

        <inertial>
          <mass>10</mass>
          <inertia>
            <ixx>0.06793646</ixx>
            <ixy>0</ixy>
            <ixz>0</ixz>
            <iyy>0.13221448</iyy>
            <iyz>0</iyz>
            <izz>0.07494388</izz>
          </inertia>
        </inertial>
  
        <inertial>
          <mass>10</mass>
          <auto>true</auto>
        </inertial>
  
        <visual name='visual'>
          <geometry>
            <mesh>
              <uri>model://ttfestcar/meshes/rascar.dae</uri>
            </mesh>
          </geometry>
        </visual>
  
        <collision name="collision">
          <geometry>
            <mesh>
              <uri>model://ttfestcar/meshes/rascar.dae</uri>
            </mesh>
          </geometry>
        </collision>
      </link>
  
      <link name='left_wheel'>
        <pose relative_to='chassis'>-0.106 0 0.022 0 1.57 0</pose>
  
        <inertial>
          <mass>10</mass>
          <inertia>
            <ixx>0.0016</ixx>
            <ixy>0</ixy>
            <ixz>0</ixz>
            <iyy>0.0016</iyy>
            <iyz>0</iyz>
            <izz>0.00088</izz>
          </inertia>
        </inertial>
  
        <visual name='visual'>
          <geometry>
            <cylinder>
              <radius>0.044</radius>
              <length>0.03</length>
            </cylinder>
          </geometry>
        </visual>
  
        <collision name="collision">
          <geometry>
            <cylinder>
              <radius>0.044</radius>
              <length>0.03</length>
            </cylinder>
          </geometry>
        </collision>
      </link>
  
      <link name='right_wheel'>
        <pose relative_to='chassis'>0.106 0 0.022 0 1.57 0</pose>
  
        <inertial>
          <mass>10</mass>
          <inertia>
            <ixx>0.0016</ixx>
            <ixy>0</ixy>
            <ixz>0</ixz>
            <iyy>0.0016</iyy>
            <iyz>0</iyz>
            <izz>0.00088</izz>
          </inertia>
        </inertial>
  
        <visual name='visual'>
          <geometry>
            <cylinder>
              <radius>0.044</radius>
              <length>0.03</length>
            </cylinder>
          </geometry>
        </visual>
  
        <collision name="collision">
          <geometry>
            <cylinder>
              <radius>0.044</radius>
              <length>0.03</length>
            </cylinder>
          </geometry>
        </collision>
      </link>
  
      <link name='caster_wheel'>
        <pose relative_to='chassis'>0 -0.1765 -0.011 0 0 0</pose>
        <inertial>
          <mass>5</mass>
          <inertia>
            <ixx>0.000242</ixx>
            <iyy>0.000242</iyy>
            <izz>0.000242</izz>
          </inertia>
        </inertial>
  
        <visual name='visual'>
          <geometry>
            <sphere>
              <radius>0.011</radius>
            </sphere>
          </geometry>
        </visual>
  
        <collision name='collision'>
          <geometry>
            <sphere>
              <radius>0.011</radius>
            </sphere>
          </geometry>
        </collision>
      </link>
  
      <joint name='left_wheel_joint' type='revolute'>
        <parent>chassis</parent>
        <child>left_wheel</child>
        <axis>
          <xyz expressed_in='__model__'>1 0 0</xyz>
          <limit>
            <lower>-1.79769e+308</lower>
            <upper>1.79769e+308</upper>
          </limit>
          <dynamics>
            <friction>12.031606150200002</friction>
          </dynamics>
        </axis>
      </joint>
  
      <joint name='right_wheel_joint' type='revolute'>
        <parent>chassis</parent>
        <child>right_wheel</child>
        <axis>
          <xyz expressed_in='__model__'>1 0 0</xyz>
          <limit>
            <lower>-1.79769e+308</lower>
            <upper>1.79769e+308</upper>
          </limit>
          <dynamics>
            <friction>12.031606150200002</friction>
          </dynamics>
        </axis>
      </joint>
  
      <joint name='caster_wheel_joint' type='ball'>
        <parent>chassis</parent>
        <child>caster_wheel</child>
        <dynamics>
          <friction>12.031606150200002</friction>
        </dynamics>
      </joint>
  
      <link name="camera_link">
        <pose relative_to="chassis">0 -0.144 0.0975 0 0 -1.57</pose>
        <inertial>
          <mass>0.1</mass>
          <inertia>
            <ixx>0.000166667</ixx>
            <iyy>0.000166667</iyy>
            <izz>0.000166667</izz>
          </inertia>
        </inertial>
  
        <visual name="visual">
          <geometry>
            <box>
              <size>0.01 0.01 0.01</size>
            </box>
          </geometry>
        </visual>
  
        <collision name="collision">
          <geometry>
            <box>
              <size>0.1 0.1 0.1</size>
            </box>
          </geometry>
        </collision>
  
        <sensor name="camera" type="camera">
          <camera>
            <horizontal_fov>1.0855947947</horizontal_fov>
            <image>
              <width>829</width>
              <height>621</height>
            </image>
            <clip>
              <near>0.1</near>
              <far>100</far>
            </clip>
          </camera>
          <plugin name="camera_controller" filename="libgazebo_ros_camera.so">
            <always_on>1</always_on>
            <update_rate>30</update_rate>
            <cameraName>/camera</cameraName>
            <imageTopicName>image_raw</imageTopicName>
            <cameraInfoTopicName>camera_info</cameraInfoTopicName>
            <frameName>camera</frameName>
          </plugin>
  
        </sensor>
      </link>
  
      <joint name='camera_joint' type='fixed'>
        <pose relative_to='camera_link' />
        <parent>chassis</parent>
        <child>camera_link</child>
      </joint>
  
      <link name="hokuyo_link">
  
  
        <sensor name="head_hokuyo_sensor" type="ray">
            <always_on>true</always_on>
            <visualize>false</visualize>
            <pose relative_to='chassis'>0 -0.155 0.054 0 0 0</pose>
            <update_rate>100</update_rate>
            <ray>
                <scan>
                    <horizontal>
                        <samples>2000</samples>
                        <resolution>0.2</resolution>
                        <min_angle>-3.14</min_angle>
                        <max_angle>3.14</max_angle>
                    </horizontal>
                </scan>
                <range>
                    <min>0.15</min>
                    <max>6.0</max>
                    <resolution>0.5</resolution>
                </range>
            </ray>
            <plugin name="gazebo_ros_head_hokuyo_controller"
                filename="libgazebo_ros_ray_sensor.so">
                <ros>
                    <namespace>/lidar</namespace>
                    <remapping>~/out:=data</remapping>
                </ros>
                <output_type>sensor_msgs/LaserScan</output_type>
                <frameName>hokuyo_link</frameName>
            </plugin>
        </sensor>
    </link>
  
    <joint name="hokuyo_joint" type="fixed">
      <parent>chassis</parent>
      <child>hokuyo_link</child>
      <pose>0 0 0 0 0 0</pose>
  </joint>
  
    </model>
    <light name='user_directional_light_0' type='directional'>
      <pose>1.00186 -0.958533 1 0 -0 0</pose>
      <diffuse>0.5 0.5 0.5 1</diffuse>
      <specular>0.1 0.1 0.1 1</specular>
      <direction>0.1 0.1 -0.9</direction>
      <attenuation>
        <range>20</range>
        <constant>0.5</constant>
        <linear>0.01</linear>
        <quadratic>0.001</quadratic>
      </attenuation>
      <cast_shadows>1</cast_shadows>
    </light>
    <light name='user_directional_light_1' type='directional'>
      <pose>-0.824597 -1.29851 1 0 -0 0</pose>
      <diffuse>0.5 0.5 0.5 1</diffuse>
      <specular>0.1 0.1 0.1 1</specular>
      <direction>0.1 0.1 -0.9</direction>
      <attenuation>
        <range>20</range>
        <constant>0.5</constant>
        <linear>0.01</linear>
        <quadratic>0.001</quadratic>
      </attenuation>
      <cast_shadows>1</cast_shadows>
    </light>
    <light name='user_directional_light_2' type='directional'>
      <pose>-0.482094 -1.05082 1 0 -0 0</pose>
      <diffuse>0.5 0.5 0.5 1</diffuse>
      <specular>0.1 0.1 0.1 1</specular>
      <direction>0.1 0.1 -0.9</direction>
      <attenuation>
        <range>20</range>
        <constant>0.5</constant>
        <linear>0.01</linear>
        <quadratic>0.001</quadratic>
      </attenuation>
      <cast_shadows>1</cast_shadows>
    </light>
    <light name='user_directional_light_3' type='directional'>
      <pose>-0.490253 -1.08654 1 0 -0 0</pose>
      <diffuse>0.5 0.5 0.5 1</diffuse>
      <specular>0.1 0.1 0.1 1</specular>
      <direction>0.1 0.1 -0.9</direction>
      <attenuation>
        <range>20</range>
        <constant>0.5</constant>
        <linear>0.01</linear>
        <quadratic>0.001</quadratic>
      </attenuation>
      <cast_shadows>1</cast_shadows>
    </light>
    <model name='TtfestRoad'>
      <static>1</static>
      <link name='link'>
        <pose>0 0 0 0 -0 0</pose>
        <collision name='collision'>
          <geometry>
            <mesh>
              <uri>model://ttfestroad/meshes/road.dae</uri>
              <scale>1 1 1</scale>
            </mesh>
          </geometry>
          <max_contacts>10</max_contacts>
          <surface>
            <contact>
              <ode/>
            </contact>
            <bounce/>
            <friction>
              <torsional>
                <ode/>
              </torsional>
              <ode/>
            </friction>
          </surface>
        </collision>
        <visual name='visual'>
          <geometry>
            <mesh>
              <uri>model://ttfestroad/meshes/road.dae</uri>
              <scale>1 1 1</scale>
            </mesh>
          </geometry>
        </visual>
        <self_collide>0</self_collide>
        <enable_wind>0</enable_wind>
        <kinematic>0</kinematic>
      </link>
      <pose>1.02256 -2.60892 0 0 -0 0</pose>
    </model>
    <state world_name='default'>
      <sim_time>58 37000000</sim_time>
      <real_time>447 583521418</real_time>
      <wall_time>1715703017 598887177</wall_time>
      <iterations>58037</iterations>
      <model name='TtfestRoad'>
        <pose>1.02256 -2.60892 0 0 -0 0</pose>
        <scale>1 1 1</scale>
        <link name='link'>
          <pose>1.02256 -2.60892 0 0 -0 0</pose>
          <velocity>0 0 0 0 -0 0</velocity>
          <acceleration>0 0 0 0 -0 0</acceleration>
          <wrench>0 0 0 0 -0 0</wrench>
        </link>
      </model>
      <model name='ttfestcar'>
        <pose>5.46549 2.16962 2.4e-05 6.4e-05 -0 -1.56803</pose>
        <scale>1 1 1</scale>
        <link name='camera_link'>
          <pose>5.32148 2.16922 0.154015 1e-06 6.5e-05 -3.13803</pose>
          <velocity>-0.00014 -0.000267 -5e-05 -0.001353 -0.000561 0.000274</velocity>
          <acceleration>0.592632 0.164004 -7.43667 0.1994 -0.567193 0.304953</acceleration>
          <wrench>0.059263 0.0164 -0.743667 0 -0 0</wrench>
        </link>
        <link name='caster_wheel'>
          <pose>5.28899 2.16913 0.029512 0.119839 0.379439 -1.5472</pose>
          <velocity>-6.8e-05 -0.000516 2.9e-05 0.017481 -0.002301 0</velocity>
          <acceleration>-0.083485 0.046542 -6.84868 1.54283 -0.310877 3.14159</acceleration>
          <wrench>-0.417427 0.232708 -34.2434 0 -0 0</wrench>
        </link>
        <link name='chassis'>
          <pose>5.46548 2.16962 0.059024 6.4e-05 -0 -1.56803</pose>
          <velocity>-8.9e-05 -0.000459 0.000123 -0.001454 -0.000735 0.000125</velocity>
          <acceleration>0.067346 0.027913 -7.92519 0.014635 -1.13882 0.019784</acceleration>
          <wrench>0.673459 0.279128 -79.2519 0 -0 0</wrench>
        </link>
        <link name='hokuyo_link'>
          <pose>5.46549 2.16962 2.4e-05 6.4e-05 -0 -1.56803</pose>
          <velocity>-4.5e-05 -0.00054 0.000123 -0.001448 -0.000755 0.000129</velocity>
          <acceleration>-0.229279 0.039717 -7.92371 0.018916 -1.2368 0.028541</acceleration>
          <wrench>-0.229279 0.039717 -7.92371 0 -0 0</wrench>
        </link>
        <link name='left_wheel'>
          <pose>5.46519 2.27562 0.044024 -1.51125 1.55797 -3.07927</pose>
          <velocity>-8.8e-05 -0.000509 -3.5e-05 -0.009711 -0.000758 -0.000179</velocity>
          <acceleration>-0.003076 -0.038207 -7.93438 1.82699 0.484175 2.7221</acceleration>
          <wrench>-0.03076 -0.382072 -79.3438 0 -0 0</wrench>
        </link>
        <link name='right_wheel'>
          <pose>5.46578 2.06362 0.044024 -1.53238 1.55093 -3.10041</pose>
          <velocity>-6.1e-05 -0.000504 0.000276 -0.009829 -0.000758 -0.000236</velocity>
          <acceleration>0.001028 -0.02229 -7.93777 1.44494 1.37878 2.66754</acceleration>
          <wrench>0.010282 -0.222896 -79.3777 0 -0 0</wrench>
        </link>
      </model>
      <light name='user_directional_light_0'>
        <pose>1.00186 -0.958533 1 1.57 -0 0</pose>
      </light>
      <light name='user_directional_light_1'>
        <pose>-0.824597 -1.29851 1 -1.57 -0 0</pose>
      </light>
      <light name='user_directional_light_2'>
        <pose>-0.482094 -1.05082 1 0 -1.57 0</pose>
      </light>
      <light name='user_directional_light_3'>
        <pose>-0.490253 -1.08654 1 0 1.57 0</pose>
      </light>
    </state>
    <gui fullscreen='0'>
      <camera name='user_camera'>
        <pose>13.2935 5.49704 6.12831 0 0.447646 -2.723</pose>
        <view_controller>orbit</view_controller>
        <projection_type>perspective</projection_type>
      </camera>
    </gui>
  </world>
</sdf>
